Workbook
Name AvgOutLoad: data!$V$2
Name dataheaders: Table1[#Headers]
Name MaxKVload: data!$S$2
Name maxNthreshold: data!$BB$2
Name MaxTok: data!$AC$2
Name pivotby1: _xlfn.DROP(_xlfn.ANCHORARRAY(scatter!$A$3),1,0)

Sheet pivot-ITL
A1: E2E | B1: (All)
A2: B-ITL | B2: (All)
A3: B-Run | B3: (All)
A4: B-tok/req | B4: (All)
A5: In-Tok | B5: (All)
A6: Out-Tok | B6: (All)
A8: Average of ITL | B8: Column Labels
B9: 46104 | F9: 23/03/2026 Total | G9: 46092 | O9: 11/03/2026 Total
A10: Row Labels | B10: 1-15K,300 | C10: 5K,100-1800 | D10: 5K,200 | E10: 5K,500 | G10: 1-15K,300 | H10: 3K,100-1800 | I10: 5K,100-1800 | J10: 5K,1K | K10: 5K,200 | L10: 5K,300 | M10: 5K,500 | N10: 6K,100
A11: 0.010150558 | G11: 0.0065961989 | O11: 0.0065961989
A12: 0.011850272 | B12: 0.006621296 | F12: 0.006621296
A13: 0.016512173 | G13: 0.0070278515 | O13: 0.0070278515
A14: 0.016875257 | H14: 0.0084535996 | O14: 0.0084535996
A15: 0.019997642 | G15: 0.0072804041 | O15: 0.0072804041
A16: 0.025965865 | B16: 0.0074908518 | F16: 0.0074908518
A17: 0.027674918 | I17: 0.0096372251 | O17: 0.0096372251
A18: 0.031234376 | C18: 0.0096815497 | F18: 0.0096815497
A19: 0.035640373 | G19: 0.0080706953 | O19: 0.0080706953
A20: 0.036869666 | B20: 0.0081016796 | F20: 0.0081016796
A21: 0.039849347 | G21: 0.0082483981 | O21: 0.0082483981
A22: 0.041308812 | H22: 0.0090757149 | O22: 0.0090757149
A23: 0.044642703 | N23: 0.011061017 | O23: 0.011061017
A24: 0.046332213 | N24: 0.011654575 | O24: 0.011654575
A25: 0.055009626 | N25: 0.018346192 | O25: 0.018346192
A26: 0.055108174 | G26: 0.0090297684 | O26: 0.0090297684
A27: 0.057327386 | C27: 0.0099585362 | F27: 0.0099585362
A28: 0.057532059 | G28: 0.0093669172 | O28: 0.0093669172
A29: 0.05821955 | B29: 0.0090222427 | F29: 0.0090222427
A30: 0.058994914 | K30: 0.010721021 | O30: 0.010721021
A31: 0.059106974 | N31: 0.013275208 | O31: 0.013275208
A32: 0.059313421 | D32: 0.0096212234 | F32: 0.0096212234
A33: 0.060624515 | D33: 0.011228163 | F33: 0.011228163
A34: 0.062301221 | I34: 0.010460084 | O34: 0.010460084
A35: 0.063554866 | D35: 0.010864383 | F35: 0.010864383
A36: 0.063885297 | K36: 0.011288193 | O36: 0.011288193
A37: 0.068267103 | N37: 0.014768636 | O37: 0.014768636
A38: 0.068285949 | H38: 0.0097737484 | O38: 0.0097737484
A39: 0.069947993 | K39: 0.010464462 | O39: 0.010464462
A40: 0.071823119 | D40: 0.011404411 | F40: 0.011404411
A41: 0.078173154 | G41: 0.010746412 | O41: 0.010746412
...

Sheet ITL
A1: ='pivot-ITL'!A8 -> Average of ITL | B1: ='pivot-ITL'!B8 -> Column Labels | C1: ='pivot-ITL'!C8 -> 0 | D1: ='pivot-ITL'!D8 -> 0 | E1: ='pivot-ITL'!E8 -> 0 | F1: ='pivot-ITL'!F8 -> 0 | G1: ='pivot-ITL'!G8 -> 0 | H1: ='pivot-ITL'!H8 -> 0 | I1: ='pivot-ITL'!I8 -> 0
A2: Average of ITL | B2: 1-15K,300 | C2: 3K,100-1800 | D2: 5K,100-1800 | E2: 5K,1K | F2: 5K,200 | G2: 5K,300 | H2: 5K,500 | I2: 6K,100 | X2: X | Y2: Y
A3: 0.02 | B3: 0.0069681515 | C3: 0.0084535996 | D3: #N/A | E3: #N/A | F3: #N/A | G3: #N/A | H3: #N/A | I3: #N/A | X3: =Table2[[#This Row],[Average of ITL]] -> 0.02 | Y3: =_xlfn.IFNA(Table2[[#This Row],[6K,100]],"")
A4: 0.03 | B4: #N/A | C4: #N/A | D4: 0.0096372251 | E4: #N/A | F4: #N/A | G4: #N/A | H4: #N/A | I4: #N/A | X4: =Table2[[#This Row],[Average of ITL]] -> 0.03 | Y4: =_xlfn.IFNA(Table2[[#This Row],[6K,100]],"")
A5: 0.04 | B5: 0.0081595467 | C5: #N/A | D5: #N/A | E5: #N/A | F5: #N/A | G5: #N/A | H5: #N/A | I5: #N/A | X5: =Table2[[#This Row],[Average of ITL]] -> 0.04 | Y5: =_xlfn.IFNA(Table2[[#This Row],[6K,100]],"") | AB5: KV% | AC5: ITL[6k,100] | AD5: EST
A6: 0.05 | B6: #N/A | C6: 0.0090757149 | D6: #N/A | E6: #N/A | F6: #N/A | G6: #N/A | H6: #N/A | I6: 0.011357796 | X6: =Table2[[#This Row],[Average of ITL]] -> 0.05 | Y6: =_xlfn.IFNA(Table2[[#This Row],[6K,100]],"") -> 0.011357796 | AB6: 0.05 | AC6: 0.011357796 | AD6: {=TREND(AC6:AC27,AB6:AB27)} -> 0.012289916 | AE6: {=TREND(AC6:AC27,AB6:AB27,0.8)} -> 0.10346161
A7: 0.06 | B7: 0.0091983428 | C7: #N/A | D7: #N/A | E7: #N/A | F7: 0.010721021 | G7: #N/A | H7: #N/A | I7: 0.0158107 | X7: =Table2[[#This Row],[Average of ITL]] -> 0.06 | Y7: =_xlfn.IFNA(Table2[[#This Row],[6K,100]],"") -> 0.0158107 | AB7: 0.06 | AC7: 0.0158107 | AD7: 0.013505538
A8: 0.07 | B8: #N/A | C8: 0.0097737484 | D8: 0.010460084 | E8: #N/A | F8: 0.010876328 | G8: #N/A | H8: #N/A | I8: 0.014768636 | X8: =Table2[[#This Row],[Average of ITL]] -> 0.07 | Y8: =_xlfn.IFNA(Table2[[#This Row],[6K,100]],"") -> 0.014768636 | AB8: 0.07 | AC8: 0.014768636 | AD8: 0.014721161
A9: 0.08 | B9: 0.010746412 | C9: #N/A | D9: #N/A | E9: #N/A | F9: #N/A | G9: #N/A | H9: #N/A | I9: 0.015918493 | X9: =Table2[[#This Row],[Average of ITL]] -> 0.08 | Y9: =_xlfn.IFNA(Table2[[#This Row],[6K,100]],"") -> 0.015918493 | AB9: 0.08 | AC9: 0.015918493 | AD9: 0.015936784
A10: 0.09 | B10: #N/A | C10: #N/A | D10: #N/A | E10: #N/A | F10: 0.011873789 | G10: 0.011154069 | H10: #N/A | I10: 0.01508635 | X10: =Table2[[#This Row],[Average of ITL]] -> 0.09 | Y10: =_xlfn.IFNA(Table2[[#This Row],[6K,100]],"") -> 0.01508635 | AB10: 0.09 | AC10: 0.01508635 | AD10: 0.017152406
A11: 0.1 | B11: #N/A | C11: 0.010705458 | D11: 0.011342318 | E11: #N/A | F11: 0.014219892 | G11: #N/A | H11: #N/A | I11: #N/A | X11: =Table2[[#This Row],[Average of ITL]] -> 0.1 | Y11: =_xlfn.IFNA(Table2[[#This Row],[6K,100]],"") | AB11: 0.14 | AC11: 0.022143876 | AD11: 0.023230519
A12: 0.11 | B12: #N/A | C12: #N/A | D12: 0.011075834 | E12: #N/A | F12: 0.013731578 | G12: #N/A | H12: #N/A | I12: #N/A | X12: =Table2[[#This Row],[Average of ITL]] -> 0.11 | Y12: =_xlfn.IFNA(Table2[[#This Row],[6K,100]],"") | AB12: 0.16 | AC12: 0.024129972 | AD12: 0.025661764
A13: 0.12 | B13: #N/A | C13: 0.010615078 | D13: #N/A | E13: #N/A | F13: #N/A | G13: #N/A | H13: #N/A | I13: #N/A | X13: =Table2[[#This Row],[Average of ITL]] -> 0.12 | Y13: =_xlfn.IFNA(Table2[[#This Row],[6K,100]],"") | AB13: 0.21 | AC13: 0.031643051 | AD13: 0.031739877
A14: 0.13 | B14: #N/A | C14: #N/A | D14: #N/A | E14: #N/A | F14: 0.016155173 | G14: #N/A | H14: #N/A | I14: #N/A | X14: =Table2[[#This Row],[Average of ITL]] -> 0.13 | Y14: =_xlfn.IFNA(Table2[[#This Row],[6K,100]],"") | AB14: 0.22 | AC14: 0.035378278 | AD14: 0.0329555
A15: 0.14 | B15: 0.013541517 | C15: #N/A | D15: #N/A | E15: #N/A | F15: #N/A | G15: #N/A | H15: #N/A | I15: 0.022143876 | X15: =Table2[[#This Row],[Average of ITL]] -> 0.14 | Y15: =_xlfn.IFNA(Table2[[#This Row],[6K,100]],"") -> 0.022143876 | AB15: 0.24 | AC15: 0.038194115 | AD15: 0.035386745
A16: 0.15 | B16: #N/A | C16: #N/A | D16: #N/A | E16: #N/A | F16: 0.018282164 | G16: #N/A | H16: #N/A | I16: #N/A | X16: =Table2[[#This Row],[Average of ITL]] -> 0.15 | Y16: =_xlfn.IFNA(Table2[[#This Row],[6K,100]],"") | AB16: 0.33 | AC16: 0.045377524 | AD16: 0.046327348
A17: 0.16 | B17: #N/A | C17: 0.01150518 | D17: #N/A | E17: #N/A | F17: #N/A | G17: #N/A | H17: #N/A | I17: 0.024129972 | X17: =Table2[[#This Row],[Average of ITL]] -> 0.16 | Y17: =_xlfn.IFNA(Table2[[#This Row],[6K,100]],"") -> 0.024129972 | AB17: 0.4 | AC17: 0.056983425 | AD17: 0.054836706
A18: 0.17 | B18: #N/A | C18: 0.011636336 | D18: #N/A | E18: #N/A | F18: #N/A | G18: #N/A | H18: #N/A | I18: #N/A | X18: =Table2[[#This Row],[Average of ITL]] -> 0.17 | Y18: =_xlfn.IFNA(Table2[[#This Row],[6K,100]],"") | AB18: 0.41 | AC18: 0.055761779 | AD18: 0.056052329
A19: 0.18 | B19: 0.015553108 | C19: #N/A | D19: #N/A | E19: #N/A | F19: 0.018460602 | G19: #N/A | H19: 0.01346446 | I19: #N/A | X19: =Table2[[#This Row],[Average of ITL]] -> 0.18 | Y19: =_xlfn.IFNA(Table2[[#This Row],[6K,100]],"") | AB19: 0.54 | AC19: 0.070172334 | AD19: 0.071855422
A20: 0.19 | B20: 0.016170002 | C20: #N/A | D20: #N/A | E20: #N/A | F20: #N/A | G20: #N/A | H20: #N/A | I20: #N/A | X20: =Table2[[#This Row],[Average of ITL]] -> 0.19 | Y20: =_xlfn.IFNA(Table2[[#This Row],[6K,100]],"") | AB20: 0.7 | AC20: 0.084682442 | AD20: 0.091305384
A21: 0.21 | B21: #N/A | C21: #N/A | D21: #N/A | E21: #N/A | F21: #N/A | G21: #N/A | H21: #N/A | I21: 0.031643051 | X21: =Table2[[#This Row],[Average of ITL]] -> 0.21 | Y21: =_xlfn.IFNA(Table2[[#This Row],[6K,100]],"") -> 0.031643051 | AB21: 0.72 | AC21: 0.090844477 | AD21: 0.093736629
A22: 0.22 | B22: #N/A | C22: #N/A | D22: 0.015406034 | E22: #N/A | F22: #N/A | G22: #N/A | H22: 0.014772788 | I22: 0.035378278 | X22: =Table2[[#This Row],[Average of ITL]] -> 0.22 | Y22: =_xlfn.IFNA(Table2[[#This Row],[6K,100]],"") -> 0.035378278 | AB22: 0.74 | AC22: 0.097520763 | AD22: 0.096167874
A23: 0.23 | B23: #N/A | C23: #N/A | D23: #N/A | E23: #N/A | F23: 0.022218246 | G23: 0.019149388 | H23: #N/A | I23: #N/A | X23: =Table2[[#This Row],[Average of ITL]] -> 0.23 | Y23: =_xlfn.IFNA(Table2[[#This Row],[6K,100]],"") | AB23: 0.76 | AC23: 0.1046268 | AD23: 0.098599119
A24: 0.24 | B24: #N/A | C24: #N/A | D24: #N/A | E24: #N/A | F24: #N/A | G24: #N/A | H24: 0.015582202 | I24: 0.038194115 | X24: =Table2[[#This Row],[Average of ITL]] -> 0.24 | Y24: =_xlfn.IFNA(Table2[[#This Row],[6K,100]],"") -> 0.038194115 | AB24: 0.77 | AC24: 0.10106962 | AD24: 0.099814742
A25: 0.25 | B25: #N/A | C25: 0.013493247 | D25: 0.014934354 | E25: #N/A | F25: #N/A | G25: #N/A | H25: #N/A | I25: #N/A | X25: =Table2[[#This Row],[Average of ITL]] -> 0.25 | Y25: =_xlfn.IFNA(Table2[[#This Row],[6K,100]],"") | AB25: 0.79 | AC25: 0.096583569 | AD25: 0.10224599
A26: 0.26 | B26: #N/A | C26: #N/A | D26: #N/A | E26: #N/A | F26: #N/A | G26: #N/A | H26: 0.01607343 | I26: #N/A | X26: =Table2[[#This Row],[Average of ITL]] -> 0.26 | Y26: =_xlfn.IFNA(Table2[[#This Row],[6K,100]],"") | AB26: 0.8 | AC26: 0.10782965 | AD26: 0.10346161
A27: 0.27 | B27: #N/A | C27: #N/A | D27: #N/A | E27: #N/A | F27: #N/A | G27: #N/A | H27: 0.017040465 | I27: #N/A | X27: =Table2[[#This Row],[Average of ITL]] -> 0.27 | Y27: =_xlfn.IFNA(Table2[[#This Row],[6K,100]],"") | AB27: 0.85 | AC27: 0.11063944 | AD27: 0.10953972
A28: 0.28 | B28: 0.020987859 | C28: #N/A | D28: #N/A | E28: #N/A | F28: #N/A | G28: #N/A | H28: #N/A | I28: #N/A | X28: =Table2[[#This Row],[Average of ITL]] -> 0.28 | Y28: =_xlfn.IFNA(Table2[[#This Row],[6K,100]],"")
A29: 0.29 | B29: #N/A | C29: #N/A | D29: #N/A | E29: #N/A | F29: 0.025528575 | G29: #N/A | H29: #N/A | I29: #N/A | X29: =Table2[[#This Row],[Average of ITL]] -> 0.29 | Y29: =_xlfn.IFNA(Table2[[#This Row],[6K,100]],"")
A30: 0.3 | B30: #N/A | C30: #N/A | D30: 0.01607506 | E30: #N/A | F30: 0.026751556 | G30: #N/A | H30: #N/A | I30: #N/A | X30: =Table2[[#This Row],[Average of ITL]] -> 0.3 | Y30: =_xlfn.IFNA(Table2[[#This Row],[6K,100]],"")
A31: 0.31 | B31: #N/A | C31: #N/A | D31: #N/A | E31: #N/A | F31: #N/A | G31: #N/A | H31: 0.017937609 | I31: #N/A | X31: =Table2[[#This Row],[Average of ITL]] -> 0.31 | Y31: =_xlfn.IFNA(Table2[[#This Row],[6K,100]],"")
A32: 0.32 | B32: #N/A | C32: #N/A | D32: 0.016149981 | E32: #N/A | F32: #N/A | G32: #N/A | H32: #N/A | I32: #N/A | X32: =Table2[[#This Row],[Average of ITL]] -> 0.32 | Y32: =_xlfn.IFNA(Table2[[#This Row],[6K,100]],"")
A33: 0.33 | B33: #N/A | C33: #N/A | D33: #N/A | E33: #N/A | F33: #N/A | G33: #N/A | H33: #N/A | I33: 0.045377524 | X33: =Table2[[#This Row],[Average of ITL]] -> 0.33 | Y33: =_xlfn.IFNA(Table2[[#This Row],[6K,100]],"") -> 0.045377524
A34: 0.34 | B34: 0.024352672 | C34: #N/A | D34: #N/A | E34: #N/A | F34: #N/A | G34: 0.024075493 | H34: 0.019511345 | I34: #N/A | X34: =Table2[[#This Row],[Average of ITL]] -> 0.34 | Y34: =_xlfn.IFNA(Table2[[#This Row],[6K,100]],"")
A35: 0.36 | B35: #N/A | C35: 0.01646855 | D35: #N/A | E35: #N/A | F35: #N/A | G35: #N/A | H35: #N/A | I35: #N/A | X35: =Table2[[#This Row],[Average of ITL]] -> 0.36 | Y35: =_xlfn.IFNA(Table2[[#This Row],[6K,100]],"")
A36: 0.37 | B36: #N/A | C36: #N/A | D36: #N/A | E36: #N/A | F36: 0.031966867 | G36: #N/A | H36: #N/A | I36: #N/A | X36: =Table2[[#This Row],[Average of ITL]] -> 0.37 | Y36: =_xlfn.IFNA(Table2[[#This Row],[6K,100]],"")
A37: 0.38 | B37: #N/A | C37: 0.01749442 | D37: #N/A | E37: #N/A | F37: #N/A | G37: #N/A | H37: #N/A | I37: #N/A | X37: =Table2[[#This Row],[Average of ITL]] -> 0.38 | Y37: =_xlfn.IFNA(Table2[[#This Row],[6K,100]],"")
A38: 0.4 | B38: #N/A | C38: #N/A | D38: 0.017961932 | E38: #N/A | F38: #N/A | G38: #N/A | H38: #N/A | I38: 0.056983425 | X38: =Table2[[#This Row],[Average of ITL]] -> 0.4 | Y38: =_xlfn.IFNA(Table2[[#This Row],[6K,100]],"") -> 0.056983425
A39: 0.41 | B39: #N/A | C39: #N/A | D39: #N/A | E39: #N/A | F39: #N/A | G39: #N/A | H39: #N/A | I39: 0.055761779 | X39: =Table2[[#This Row],[Average of ITL]] -> 0.41 | Y39: =_xlfn.IFNA(Table2[[#This Row],[6K,100]],"") -> 0.055761779
A40: 0.42 | B40: #N/A | C40: 0.017667547 | D40: #N/A | E40: 0.019820489 | F40: 0.038099702 | G40: #N/A | H40: #N/A | I40: #N/A | X40: =Table2[[#This Row],[Average of ITL]] -> 0.42 | Y40: =_xlfn.IFNA(Table2[[#This Row],[6K,100]],"")
...

Sheet pivot-prefill
A1: In-Tok | B1: (All)
A2: RPS | B2: (All)
B4: Column Labels
B5: 5K,1K | D5: 5K,200 | F5: 5K,300 | H5: 5K,500 | J5: 6K,100 | AA5: Average of Prefill | AB5: 1-15K,300 | AC5: 3K,100-1800 | AD5: 5K,100-1800 | AE5: 5K,1K | AF5: 5K,200 | AG5: 5K,300 | AH5: 5K,500 | AI5: 6K,100
A6: Row Labels | B6: Average of Run | C6: Average of Prefill | D6: Average of Run | E6: Average of Prefill | F6: Average of Run | G6: Average of Prefill | H6: Average of Run | I6: Average of Prefill | J6: Average of Run | K6: Average of Prefill | AA6: 0.010150558 | AB6: 0.032088905 | AC6: #N/A | AD6: #N/A | AE6: #N/A | AF6: #N/A | AG6: #N/A | AH6: #N/A | AI6: #N/A
A7: 0.05 | J7: 2.9074074 | K7: 0.18337235 | AA7: 0.016512173 | AB7: 0.033712867 | AC7: #N/A | AD7: #N/A | AE7: #N/A | AF7: #N/A | AG7: #N/A | AH7: #N/A | AI7: #N/A
A8: 0.06 | D8: 4.4907407 | E8: 0.14609779 | J8: 3.6481481 | K8: 0.20840024 | AA8: 0.016875257 | AB8: #N/A | AC8: 0.084236844 | AD8: #N/A | AE8: #N/A | AF8: #N/A | AG8: #N/A | AH8: #N/A | AI8: #N/A
A9: 0.07 | D9: 4.8953704 | E9: 0.1510088 | J9: 4.3703704 | K9: 0.20094197 | AA9: 0.019997642 | AB9: 0.054781456 | AC9: #N/A | AD9: #N/A | AE9: #N/A | AF9: #N/A | AG9: #N/A | AH9: #N/A | AI9: #N/A
A10: 0.08 | D10: 5.45 | E10: 0.16247662 | J10: 5.0740741 | K10: 0.21283559 | AA10: 0.027674918 | AB10: #N/A | AC10: #N/A | AD10: 0.14001906 | AE10: #N/A | AF10: #N/A | AG10: #N/A | AH10: #N/A | AI10: #N/A
A11: 0.09 | D11: 6.412037 | E11: 0.15414381 | F11: 6.3333333 | G11: 0.14532217 | J11: 5.1481481 | K11: 0.20026414 | AA11: 0.035640373 | AB11: 0.056468852 | AC11: #N/A | AD11: #N/A | AE11: #N/A | AF11: #N/A | AG11: #N/A | AH11: #N/A | AI11: #N/A
A12: 0.1 | D12: 7.212037 | E12: 0.16585312 | AA12: 0.039849347 | AB12: 0.081037996 | AC12: #N/A | AD12: #N/A | AE12: #N/A | AF12: #N/A | AG12: #N/A | AH12: #N/A | AI12: #N/A
A13: 0.11 | D13: 7.7037037 | E13: 0.16607952 | AA13: 0.041308812 | AB13: #N/A | AC13: 0.089675798 | AD13: #N/A | AE13: #N/A | AF13: #N/A | AG13: #N/A | AH13: #N/A | AI13: #N/A
A14: 0.13 | D14: 9.7407407 | E14: 0.18404528 | AA14: 0.044642703 | AB14: #N/A | AC14: #N/A | AD14: #N/A | AE14: #N/A | AF14: #N/A | AG14: #N/A | AH14: #N/A | AI14: 0.18273022
A15: 0.14 | D15: 9.9944444 | E15: 0.18370498 | J15: 8.8518519 | K15: 0.24826633 | AA15: 0.046332213 | AB15: #N/A | AC15: #N/A | AD15: #N/A | AE15: #N/A | AF15: #N/A | AG15: #N/A | AH15: #N/A | AI15: 0.18401448
A16: 0.15 | D16: 10.740741 | E16: 0.20070684 | H16: 10.633333 | I16: 0.15313947 | AA16: 0.055009626 | AB16: #N/A | AC16: #N/A | AD16: #N/A | AE16: #N/A | AF16: #N/A | AG16: #N/A | AH16: #N/A | AI16: 0.22444158
A17: 0.16 | D17: 12.05 | E17: 0.1740129 | J17: 9.9259259 | K17: 0.2650008 | AA17: 0.055108174 | AB17: 0.10961615 | AC17: #N/A | AD17: #N/A | AE17: #N/A | AF17: #N/A | AG17: #N/A | AH17: #N/A | AI17: #N/A
A18: 0.18 | D18: 13 | E18: 0.20060908 | H18: 12.926471 | I18: 0.15110482 | AA18: 0.057532059 | AB18: 0.090780137 | AC18: #N/A | AD18: #N/A | AE18: #N/A | AF18: #N/A | AG18: #N/A | AH18: #N/A | AI18: #N/A
A19: 0.19 | D19: 13.875 | E19: 0.18713431 | AA19: 0.058994914 | AB19: #N/A | AC19: #N/A | AD19: #N/A | AE19: #N/A | AF19: 0.1488431 | AG19: #N/A | AH19: #N/A | AI19: #N/A
A20: 0.21 | D20: 15.3 | E20: 0.20479114 | J20: 12.962963 | K20: 0.3443539 | AA20: 0.059106974 | AB20: #N/A | AC20: #N/A | AD20: #N/A | AE20: #N/A | AF20: #N/A | AG20: #N/A | AH20: #N/A | AI20: 0.1923589
A21: 0.22 | H21: 16.021569 | I21: 0.15906984 | J21: 13.555556 | K21: 0.3306239 | AA21: 0.062301221 | AB21: #N/A | AC21: #N/A | AD21: 0.1413164 | AE21: #N/A | AF21: #N/A | AG21: #N/A | AH21: #N/A | AI21: #N/A
A22: 0.23 | D22: 17.407407 | E22: 0.21021472 | F22: 17.313369 | G22: 0.26971128 | AA22: 0.063885297 | AB22: #N/A | AC22: #N/A | AD22: #N/A | AE22: #N/A | AF22: 0.15019184 | AG22: #N/A | AH22: #N/A | AI22: #N/A
A23: 0.24 | H23: 17.590196 | I23: 0.16688995 | J23: 14.888889 | K23: 0.49033358 | AA23: 0.068267103 | AB23: #N/A | AC23: #N/A | AD23: #N/A | AE23: #N/A | AF23: #N/A | AG23: #N/A | AH23: #N/A | AI23: 0.20094197
A24: 0.26 | D24: 19.45 | E24: 0.21398529 | H24: 18.705882 | I24: 0.17102829 | AA24: 0.068285949 | AB24: #N/A | AC24: 0.089116245 | AD24: #N/A | AE24: #N/A | AF24: #N/A | AG24: #N/A | AH24: #N/A | AI24: #N/A
A25: 0.27 | H25: 19.601103 | I25: 0.1847855 | AA25: 0.069947993 | AB25: #N/A | AC25: #N/A | AD25: #N/A | AE25: #N/A | AF25: 0.14817791 | AG25: #N/A | AH25: #N/A | AI25: #N/A
A26: 0.28 | H26: 20.666667 | I26: 0.16331144 | AA26: 0.078173154 | AB26: 0.1418856 | AC26: #N/A | AD26: #N/A | AE26: #N/A | AF26: #N/A | AG26: #N/A | AH26: #N/A | AI26: #N/A
A27: 0.29 | D27: 21.407407 | E27: 0.25286004 | AA27: 0.079329368 | AB27: #N/A | AC27: #N/A | AD27: #N/A | AE27: #N/A | AF27: #N/A | AG27: #N/A | AH27: #N/A | AI27: 0.21283559
A28: 0.3 | D28: 22.199074 | E28: 0.25441059 | AA28: 0.080174123 | AB28: #N/A | AC28: #N/A | AD28: #N/A | AE28: #N/A | AF28: 0.15084291 | AG28: #N/A | AH28: #N/A | AI28: #N/A
A29: 0.31 | H29: 22.841912 | I29: 0.17878857 | AA29: 0.080536161 | AB29: #N/A | AC29: #N/A | AD29: #N/A | AE29: #N/A | AF29: #N/A | AG29: #N/A | AH29: #N/A | AI29: 0.20026414
A30: 0.33 | J30: 21 | K30: 0.38217349 | AA30: 0.084433993 | AB30: #N/A | AC30: #N/A | AD30: #N/A | AE30: #N/A | AF30: #N/A | AG30: 0.14532217 | AH30: #N/A | AI30: #N/A
A31: 0.34 | F31: 25.670308 | G31: 0.24776598 | H31: 25.029412 | I31: 0.18453547 | AA31: 0.093204609 | AB31: #N/A | AC31: #N/A | AD31: #N/A | AE31: #N/A | AF31: 0.16534524 | AG31: #N/A | AH31: #N/A | AI31: #N/A
A32: 0.37 | D32: 27.465278 | E32: 0.4245559 | AA32: 0.095071419 | AB32: #N/A | AC32: #N/A | AD32: 0.14455132 | AE32: #N/A | AF32: #N/A | AG32: #N/A | AH32: #N/A | AI32: #N/A
A33: 0.4 | H33: 29.066667 | I33: 0.18832898 | J33: 25.074074 | K33: 0.58959784 | AA33: 0.098829462 | AB33: #N/A | AC33: 0.091278881 | AD33: #N/A | AE33: #N/A | AF33: #N/A | AG33: #N/A | AH33: #N/A | AI33: #N/A
A34: 0.41 | J34: 26.222222 | K34: 0.50133486 | AA34: 0.10154584 | AB34: #N/A | AC34: #N/A | AD34: #N/A | AE34: #N/A | AF34: 0.16607952 | AG34: #N/A | AH34: #N/A | AI34: #N/A
A35: 0.42 | B35: 29.425 | C35: 0.18708274 | D35: 31.962963 | E35: 0.86688896 | AA35: 0.10698368 | AB35: #N/A | AC35: #N/A | AD35: 0.14438882 | AE35: #N/A | AF35: #N/A | AG35: #N/A | AH35: #N/A | AI35: #N/A
A36: 0.47 | D36: 35.592593 | E36: 0.9873428 | F36: 35.057407 | G36: 0.94486021 | AA36: 0.11451878 | AB36: #N/A | AC36: 0.091119562 | AD36: #N/A | AE36: #N/A | AF36: #N/A | AG36: #N/A | AH36: #N/A | AI36: #N/A
A37: 0.48 | H37: 35.349074 | I37: 0.55566616 | AA37: 0.12825331 | AB37: #N/A | AC37: #N/A | AD37: #N/A | AE37: #N/A | AF37: 0.18404528 | AG37: #N/A | AH37: #N/A | AI37: #N/A
A38: 0.49 | H38: 35.857143 | I38: 0.5298049 | AA38: 0.1356726 | AB38: 0.17264718 | AC38: #N/A | AD38: #N/A | AE38: #N/A | AF38: #N/A | AG38: #N/A | AH38: #N/A | AI38: #N/A
A39: 0.5 | D39: 37.6 | E39: 0.25079317 | H39: 36.846154 | I39: 1.0975149 | AA39: 0.13641674 | AB39: 0.12824057 | AC39: #N/A | AD39: #N/A | AE39: #N/A | AF39: #N/A | AG39: #N/A | AH39: #N/A | AI39: #N/A
A40: 0.51 | H40: 37.066667 | I40: 0.18566078 | AA40: 0.13848806 | AB40: #N/A | AC40: #N/A | AD40: #N/A | AE40: #N/A | AF40: #N/A | AG40: #N/A | AH40: #N/A | AI40: 0.24826633
A41: 0.52 | H41: 37.733333 | I41: 0.19187203 | AA41: 0.14127518 | AB41: #N/A | AC41: #N/A | AD41: #N/A | AE41: #N/A | AF41: 0.20070684 | AG41: #N/A | AH41: #N/A | AI41: #N/A
...

Sheet ITL-PIVOT
A3: Average of ITL | B3: Experiment | C3: date
B4: 1-15K,300 | C4: 1-15K,300 | D4: 3K,100-1800 | E4: 5K,100-1800 | F4: 5K,100-1800 | G4: 5K,1K | H4: 5K,200 | I4: 5K,200 | J4: 5K,300 | K4: 5K,500 | L4: 5K,500 | M4: 6K,100
A5: KV% | B5: 46104 | C5: 46092 | D5: 46092 | E5: 46104 | F5: 46092 | G5: 46092 | H5: 46104 | I5: 46092 | J5: 46092 | K5: 46104 | L5: 46092 | M5: 46092
A6: 0.010150558 | C6: 0.0065961989
A7: 0.011850272 | B7: 0.006621296
A8: 0.016512173 | C8: 0.0070278515
A9: 0.016875257 | D9: 0.0084535996
A10: 0.019997642 | C10: 0.0072804041
A11: 0.025965865 | B11: 0.0074908518
A12: 0.027674918 | F12: 0.0096372251
A13: 0.031234376 | E13: 0.0096815497
A14: 0.035640373 | C14: 0.0080706953
A15: 0.036869666 | B15: 0.0081016796
A16: 0.039849347 | C16: 0.0082483981
A17: 0.041308812 | D17: 0.0090757149
A18: 0.044642703 | M18: 0.011061017
A19: 0.046332213 | M19: 0.011654575
A20: 0.055009626 | M20: 0.018346192
A21: 0.055108174 | C21: 0.0090297684
A22: 0.057327386 | E22: 0.0099585362
A23: 0.057532059 | C23: 0.0093669172
A24: 0.05821955 | B24: 0.0090222427
A25: 0.058994914 | I25: 0.010721021
A26: 0.059106974 | M26: 0.013275208
A27: 0.059313421 | H27: 0.0096212234
A28: 0.060624515 | H28: 0.011228163
A29: 0.062301221 | F29: 0.010460084
A30: 0.063554866 | H30: 0.010864383
A31: 0.063885297 | I31: 0.011288193
A32: 0.068267103 | M32: 0.014768636
A33: 0.068285949 | D33: 0.0097737484
A34: 0.069947993 | I34: 0.010464462
A35: 0.071823119 | H35: 0.011404411
A36: 0.078173154 | C36: 0.010746412
A37: 0.079329368 | M37: 0.015918493
A38: 0.080174123 | I38: 0.011873789
A39: 0.080536161 | M39: 0.01508635
A40: 0.080896043 | B40: 0.011071214
A41: 0.084433993 | J41: 0.011154069
A42: 0.08515128 | E42: 0.011780866
...

Sheet ITL-PLOT
A5: ='ITL-PIVOT'!A3 -> Average of ITL | B5: ='ITL-PIVOT'!B4 -> 1-15K,300 | C5: ='ITL-PIVOT'!C4 -> 1-15K,300 | D5: ='ITL-PIVOT'!D4 -> 3K,100-1800 | E5: ='ITL-PIVOT'!E4 -> 5K,100-1800 | F5: ='ITL-PIVOT'!F4 -> 5K,100-1800 | G5: ='ITL-PIVOT'!G4 -> 5K,1K | H5: ='ITL-PIVOT'!H4 -> 5K,200 | I5: ='ITL-PIVOT'!I4 -> 5K,200 | ... M5: ='ITL-PIVOT'!M4 -> 6K,100
A6: ='ITL-PIVOT'!A5 -> KV% | B6: ='ITL-PIVOT'!B5 -> 46104 | C6: ='ITL-PIVOT'!C5 -> 46092 | D6: ='ITL-PIVOT'!D5 -> 46092 | E6: ='ITL-PIVOT'!E5 -> 46104 | F6: ='ITL-PIVOT'!F5 -> 46092 | G6: ='ITL-PIVOT'!G5 -> 46092 | H6: ='ITL-PIVOT'!H5 -> 46104 | ... M6: ='ITL-PIVOT'!M5 -> 46092
A7: =A6 -> KV% | B7: =_xlfn.CONCAT(B5," ",TEXT(B6,"dd/mm")) -> 1-15K,300 23/03 | C7: =_xlfn.CONCAT(C5," ",TEXT(C6,"dd/mm")) -> 1-15K,300 11/03 | D7: =_xlfn.CONCAT(D5," ",TEXT(D6,"dd/mm")) -> 3K,100-1800 11/03 | E7: =_xlfn.CONCAT(E5," ",TEXT(E6,"dd/mm")) -> 5K,100-1800 23/03 | F7: =_xlfn.CONCAT(F5," ",TEXT(F6,"dd/mm")) -> 5K,100-1800 11/03 | G7: =_xlfn.CONCAT(G5," ",TEXT(G6,"dd/mm")) -> 5K,1K 11/03 | H7: =_xlfn.CONCAT(H5," ",TEXT(H6,"dd/mm")) -> 5K,200 23/03 | I7: =_xlfn.CONCAT(I5," ",TEXT(I6,"dd/mm")) -> 5K,200 11/03 | ... M7: =_xlfn.CONCAT(M5," ",TEXT(M6,"dd/mm")) -> 6K,100 11/03
A8: =IF('ITL-PIVOT'!A6=0,NA(),'ITL-PIVOT'!A6) -> 0.010150558 | B8: =IF(GETPIVOTDATA("ITL",'ITL-PIVOT'!$A$3,"KV%",$A8,"Experiment",B$5,"date",B$6)=0,NA(),GETPIVOTDATA("ITL",'ITL-PIVOT'!$A$3,"KV%",$A8,"Experiment",B$5,"date",B$6)) -> #N/A | C8: =IF(GETPIVOTDATA("ITL",'ITL-PIVOT'!$A$3,"KV%",$A8,"Experiment",C$5,"date",C$6)=0,NA(),GETPIVOTDATA("ITL",'ITL-PIVOT'!$A$3,"KV%",$A8,"Experiment",C$5,"date",C$6)) -> 0.0065961989 | D8: =IF(GETPIVOTDATA("ITL",'ITL-PIVOT'!$A$3,"KV%",$A8,"Experiment",D$5,"date",D$6)=0,NA(),GETPIVOTDATA("ITL",'ITL-PIVOT'!$A$3,"KV%",$A8,"Experiment",D$5,"date",D$6)) -> #N/A | E8: =IF(GETPIVOTDATA("ITL",'ITL-PIVOT'!$A$3,"KV%",$A8,"Experiment",E$5,"date",E$6)=0,NA(),GETPIVOTDATA("ITL",'ITL-PIVOT'!$A$3,"KV%",$A8,"Experiment",E$5,"date",E$6)) -> #N/A | F8: =IF(GETPIVOTDATA("ITL",'ITL-PIVOT'!$A$3,"KV%",$A8,"Experiment",F$5,"date",F$6)=0,NA(),GETPIVOTDATA("ITL",'ITL-PIVOT'!$A$3,"KV%",$A8,"Experiment",F$5,"date",F$6)) -> #N/A | G8: =IF(GETPIVOTDATA("ITL",'ITL-PIVOT'!$A$3,"KV%",$A8,"Experiment",G$5,"date",G$6)=0,NA(),GETPIVOTDATA("ITL",'ITL-PIVOT'!$A$3,"KV%",$A8,"Experiment",G$5,"date",G$6)) -> #N/A | H8: =IF(GETPIVOTDATA("ITL",'ITL-PIVOT'!$A$3,"KV%",$A8,"Experiment",H$5,"date",H$6)=0,NA(),GETPIVOTDATA("ITL",'ITL-PIVOT'!$A$3,"KV%",$A8,"Experiment",H$5,"date",H$6)) -> #N/A | I8: =IF(GETPIVOTDATA("ITL",'ITL-PIVOT'!$A$3,"KV%",$A8,"Experiment",I$5,"date",I$6)=0,NA(),GETPIVOTDATA("ITL",'ITL-PIVOT'!$A$3,"KV%",$A8,"Experiment",I$5,"date",I$6)) -> #N/A | ... M8: =IF(GETPIVOTDATA("ITL",'ITL-PIVOT'!$A$3,"KV%",$A8,"Experiment",M$5,"date",M$6)=0,NA(),GETPIVOTDATA("ITL",'ITL-PIVOT'!$A$3,"KV%",$A8,"Experiment",M$5,"date",M$6)) -> #N/A
A9: =IF('ITL-PIVOT'!A7=0,NA(),'ITL-PIVOT'!A7) -> 0.011850272 | B9: =IF(GETPIVOTDATA("ITL",'ITL-PIVOT'!$A$3,"KV%",$A9,"Experiment",B$5,"date",B$6)=0,NA(),GETPIVOTDATA("ITL",'ITL-PIVOT'!$A$3,"KV%",$A9,"Experiment",B$5,"date",B$6)) -> 0.006621296 | C9: =IF(GETPIVOTDATA("ITL",'ITL-PIVOT'!$A$3,"KV%",$A9,"Experiment",C$5,"date",C$6)=0,NA(),GETPIVOTDATA("ITL",'ITL-PIVOT'!$A$3,"KV%",$A9,"Experiment",C$5,"date",C$6)) -> #N/A | D9: =IF(GETPIVOTDATA("ITL",'ITL-PIVOT'!$A$3,"KV%",$A9,"Experiment",D$5,"date",D$6)=0,NA(),GETPIVOTDATA("ITL",'ITL-PIVOT'!$A$3,"KV%",$A9,"Experiment",D$5,"date",D$6)) -> #N/A | E9: =IF(GETPIVOTDATA("ITL",'ITL-PIVOT'!$A$3,"KV%",$A9,"Experiment",E$5,"date",E$6)=0,NA(),GETPIVOTDATA("ITL",'ITL-PIVOT'!$A$3,"KV%",$A9,"Experiment",E$5,"date",E$6)) -> #N/A | F9: =IF(GETPIVOTDATA("ITL",'ITL-PIVOT'!$A$3,"KV%",$A9,"Experiment",F$5,"date",F$6)=0,NA(),GETPIVOTDATA("ITL",'ITL-PIVOT'!$A$3,"KV%",$A9,"Experiment",F$5,"date",F$6)) -> #N/A | G9: =IF(GETPIVOTDATA("ITL",'ITL-PIVOT'!$A$3,"KV%",$A9,"Experiment",G$5,"date",G$6)=0,NA(),GETPIVOTDATA("ITL",'ITL-PIVOT'!$A$3,"KV%",$A9,"Experiment",G$5,"date",G$6)) -> #N/A | H9: =IF(GETPIVOTDATA("ITL",'ITL-PIVOT'!$A$3,"KV%",$A9,"Experiment",H$5,"date",H$6)=0,NA(),GETPIVOTDATA("ITL",'ITL-PIVOT'!$A$3,"KV%",$A9,"Experiment",H$5,"date",H$6)) -> #N/A | I9: =IF(GETPIVOTDATA("ITL",'ITL-PIVOT'!$A$3,"KV%",$A9,"Experiment",I$5,"date",I$6)=0,NA(),GETPIVOTDATA("ITL",'ITL-PIVOT'!$A$3,"KV%",$A9,"Experiment",I$5,"date",I$6)) -> #N/A | ... M9: =IF(GETPIVOTDATA("ITL",'ITL-PIVOT'!$A$3,"KV%",$A9,"Experiment",M$5,"date",M$6)=0,NA(),GETPIVOTDATA("ITL",'ITL-PIVOT'!$A$3,"KV%",$A9,"Experiment",M$5,"date",M$6)) -> #N/A
A10: =IF('ITL-PIVOT'!A8=0,NA(),'ITL-PIVOT'!A8) -> 0.016512173 | B10: =IF(GETPIVOTDATA("ITL",'ITL-PIVOT'!$A$3,"KV%",$A10,"Experiment",B$5,"date",B$6)=0,NA(),GETPIVOTDATA("ITL",'ITL-PIVOT'!$A$3,"KV%",$A10,"Experiment",B$5,"date",B$6)) -> #N/A | C10: =IF(GETPIVOTDATA("ITL",'ITL-PIVOT'!$A$3,"KV%",$A10,"Experiment",C$5,"date",C$6)=0,NA(),GETPIVOTDATA("ITL",'ITL-PIVOT'!$A$3,"KV%",$A10,"Experiment",C$5,"date",C$6)) -> 0.0070278515 | D10: =IF(GETPIVOTDATA("ITL",'ITL-PIVOT'!$A$3,"KV%",$A10,"Experiment",D$5,"date",D$6)=0,NA(),GETPIVOTDATA("ITL",'ITL-PIVOT'!$A$3,"KV%",$A10,"Experiment",D$5,"date",D$6)) -> #N/A | E10: =IF(GETPIVOTDATA("ITL",'ITL-PIVOT'!$A$3,"KV%",$A10,"Experiment",E$5,"date",E$6)=0,NA(),GETPIVOTDATA("ITL",'ITL-PIVOT'!$A$3,"KV%",$A10,"Experiment",E$5,"date",E$6)) -> #N/A | F10: =IF(GETPIVOTDATA("ITL",'ITL-PIVOT'!$A$3,"KV%",$A10,"Experiment",F$5,"date",F$6)=0,NA(),GETPIVOTDATA("ITL",'ITL-PIVOT'!$A$3,"KV%",$A10,"Experiment",F$5,"date",F$6)) -> #N/A | G10: =IF(GETPIVOTDATA("ITL",'ITL-PIVOT'!$A$3,"KV%",$A10,"Experiment",G$5,"date",G$6)=0,NA(),GETPIVOTDATA("ITL",'ITL-PIVOT'!$A$3,"KV%",$A10,"Experiment",G$5,"date",G$6)) -> #N/A | H10: =IF(GETPIVOTDATA("ITL",'ITL-PIVOT'!$A$3,"KV%",$A10,"Experiment",H$5,"date",H$6)=0,NA(),GETPIVOTDATA("ITL",'ITL-PIVOT'!$A$3,"KV%",$A10,"Experiment",H$5,"date",H$6)) -> #N/A | I10: =IF(GETPIVOTDATA("ITL",'ITL-PIVOT'!$A$3,"KV%",$A10,"Experiment",I$5,"date",I$6)=0,NA(),GETPIVOTDATA("ITL",'ITL-PIVOT'!$A$3,"KV%",$A10,"Experiment",I$5,"date",I$6)) -> #N/A | ... M10: =IF(GETPIVOTDATA("ITL",'ITL-PIVOT'!$A$3,"KV%",$A10,"Experiment",M$5,"date",M$6)=0,NA(),GETPIVOTDATA("ITL",'ITL-PIVOT'!$A$3,"KV%",$A10,"Experiment",M$5,"date",M$6)) -> #N/A
A11: =IF('ITL-PIVOT'!A9=0,NA(),'ITL-PIVOT'!A9) -> 0.016875257 | B11: =IF(GETPIVOTDATA("ITL",'ITL-PIVOT'!$A$3,"KV%",$A11,"Experiment",B$5,"date",B$6)=0,NA(),GETPIVOTDATA("ITL",'ITL-PIVOT'!$A$3,"KV%",$A11,"Experiment",B$5,"date",B$6)) -> #N/A | C11: =IF(GETPIVOTDATA("ITL",'ITL-PIVOT'!$A$3,"KV%",$A11,"Experiment",C$5,"date",C$6)=0,NA(),GETPIVOTDATA("ITL",'ITL-PIVOT'!$A$3,"KV%",$A11,"Experiment",C$5,"date",C$6)) -> #N/A | D11: =IF(GETPIVOTDATA("ITL",'ITL-PIVOT'!$A$3,"KV%",$A11,"Experiment",D$5,"date",D$6)=0,NA(),GETPIVOTDATA("ITL",'ITL-PIVOT'!$A$3,"KV%",$A11,"Experiment",D$5,"date",D$6)) -> 0.0084535996 | E11: =IF(GETPIVOTDATA("ITL",'ITL-PIVOT'!$A$3,"KV%",$A11,"Experiment",E$5,"date",E$6)=0,NA(),GETPIVOTDATA("ITL",'ITL-PIVOT'!$A$3,"KV%",$A11,"Experiment",E$5,"date",E$6)) -> #N/A | F11: =IF(GETPIVOTDATA("ITL",'ITL-PIVOT'!$A$3,"KV%",$A11,"Experiment",F$5,"date",F$6)=0,NA(),GETPIVOTDATA("ITL",'ITL-PIVOT'!$A$3,"KV%",$A11,"Experiment",F$5,"date",F$6)) -> #N/A | G11: =IF(GETPIVOTDATA("ITL",'ITL-PIVOT'!$A$3,"KV%",$A11,"Experiment",G$5,"date",G$6)=0,NA(),GETPIVOTDATA("ITL",'ITL-PIVOT'!$A$3,"KV%",$A11,"Experiment",G$5,"date",G$6)) -> #N/A | H11: =IF(GETPIVOTDATA("ITL",'ITL-PIVOT'!$A$3,"KV%",$A11,"Experiment",H$5,"date",H$6)=0,NA(),GETPIVOTDATA("ITL",'ITL-PIVOT'!$A$3,"KV%",$A11,"Experiment",H$5,"date",H$6)) -> #N/A | I11: =IF(GETPIVOTDATA("ITL",'ITL-PIVOT'!$A$3,"KV%",$A11,"Experiment",I$5,"date",I$6)=0,NA(),GETPIVOTDATA("ITL",'ITL-PIVOT'!$A$3,"KV%",$A11,"Experiment",I$5,"date",I$6)) -> #N/A | ... M11: =IF(GETPIVOTDATA("ITL",'ITL-PIVOT'!$A$3,"KV%",$A11,"Experiment",M$5,"date",M$6)=0,NA(),GETPIVOTDATA("ITL",'ITL-PIVOT'!$A$3,"KV%",$A11,"Experiment",M$5,"date",M$6)) -> #N/A
A12: =IF('ITL-PIVOT'!A10=0,NA(),'ITL-PIVOT'!A10) -> 0.019997642 | B12: =IF(GETPIVOTDATA("ITL",'ITL-PIVOT'!$A$3,"KV%",$A12,"Experiment",B$5,"date",B$6)=0,NA(),GETPIVOTDATA("ITL",'ITL-PIVOT'!$A$3,"KV%",$A12,"Experiment",B$5,"date",B$6)) -> #N/A | C12: =IF(GETPIVOTDATA("ITL",'ITL-PIVOT'!$A$3,"KV%",$A12,"Experiment",C$5,"date",C$6)=0,NA(),GETPIVOTDATA("ITL",'ITL-PIVOT'!$A$3,"KV%",$A12,"Experiment",C$5,"date",C$6)) -> 0.0072804041 | D12: =IF(GETPIVOTDATA("ITL",'ITL-PIVOT'!$A$3,"KV%",$A12,"Experiment",D$5,"date",D$6)=0,NA(),GETPIVOTDATA("ITL",'ITL-PIVOT'!$A$3,"KV%",$A12,"Experiment",D$5,"date",D$6)) -> #N/A | E12: =IF(GETPIVOTDATA("ITL",'ITL-PIVOT'!$A$3,"KV%",$A12,"Experiment",E$5,"date",E$6)=0,NA(),GETPIVOTDATA("ITL",'ITL-PIVOT'!$A$3,"KV%",$A12,"Experiment",E$5,"date",E$6)) -> #N/A | F12: =IF(GETPIVOTDATA("ITL",'ITL-PIVOT'!$A$3,"KV%",$A12,"Experiment",F$5,"date",F$6)=0,NA(),GETPIVOTDATA("ITL",'ITL-PIVOT'!$A$3,"KV%",$A12,"Experiment",F$5,"date",F$6)) -> #N/A | G12: =IF(GETPIVOTDATA("ITL",'ITL-PIVOT'!$A$3,"KV%",$A12,"Experiment",G$5,"date",G$6)=0,NA(),GETPIVOTDATA("ITL",'ITL-PIVOT'!$A$3,"KV%",$A12,"Experiment",G$5,"date",G$6)) -> #N/A | H12: =IF(GETPIVOTDATA("ITL",'ITL-PIVOT'!$A$3,"KV%",$A12,"Experiment",H$5,"date",H$6)=0,NA(),GETPIVOTDATA("ITL",'ITL-PIVOT'!$A$3,"KV%",$A12,"Experiment",H$5,"date",H$6)) -> #N/A | I12: =IF(GETPIVOTDATA("ITL",'ITL-PIVOT'!$A$3,"KV%",$A12,"Experiment",I$5,"date",I$6)=0,NA(),GETPIVOTDATA("ITL",'ITL-PIVOT'!$A$3,"KV%",$A12,"Experiment",I$5,"date",I$6)) -> #N/A | ... M12: =IF(GETPIVOTDATA("ITL",'ITL-PIVOT'!$A$3,"KV%",$A12,"Experiment",M$5,"date",M$6)=0,NA(),GETPIVOTDATA("ITL",'ITL-PIVOT'!$A$3,"KV%",$A12,"Experiment",M$5,"date",M$6)) -> #N/A
A13: =IF('ITL-PIVOT'!A11=0,NA(),'ITL-PIVOT'!A11) -> 0.025965865 | B13: =IF(GETPIVOTDATA("ITL",'ITL-PIVOT'!$A$3,"KV%",$A13,"Experiment",B$5,"date",B$6)=0,NA(),GETPIVOTDATA("ITL",'ITL-PIVOT'!$A$3,"KV%",$A13,"Experiment",B$5,"date",B$6)) -> 0.0074908518 | C13: =IF(GETPIVOTDATA("ITL",'ITL-PIVOT'!$A$3,"KV%",$A13,"Experiment",C$5,"date",C$6)=0,NA(),GETPIVOTDATA("ITL",'ITL-PIVOT'!$A$3,"KV%",$A13,"Experiment",C$5,"date",C$6)) -> #N/A | D13: =IF(GETPIVOTDATA("ITL",'ITL-PIVOT'!$A$3,"KV%",$A13,"Experiment",D$5,"date",D$6)=0,NA(),GETPIVOTDATA("ITL",'ITL-PIVOT'!$A$3,"KV%",$A13,"Experiment",D$5,"date",D$6)) -> #N/A | E13: =IF(GETPIVOTDATA("ITL",'ITL-PIVOT'!$A$3,"KV%",$A13,"Experiment",E$5,"date",E$6)=0,NA(),GETPIVOTDATA("ITL",'ITL-PIVOT'!$A$3,"KV%",$A13,"Experiment",E$5,"date",E$6)) -> #N/A | F13: =IF(GETPIVOTDATA("ITL",'ITL-PIVOT'!$A$3,"KV%",$A13,"Experiment",F$5,"date",F$6)=0,NA(),GETPIVOTDATA("ITL",'ITL-PIVOT'!$A$3,"KV%",$A13,"Experiment",F$5,"date",F$6)) -> #N/A | G13: =IF(GETPIVOTDATA("ITL",'ITL-PIVOT'!$A$3,"KV%",$A13,"Experiment",G$5,"date",G$6)=0,NA(),GETPIVOTDATA("ITL",'ITL-PIVOT'!$A$3,"KV%",$A13,"Experiment",G$5,"date",G$6)) -> #N/A | H13: =IF(GETPIVOTDATA("ITL",'ITL-PIVOT'!$A$3,"KV%",$A13,"Experiment",H$5,"date",H$6)=0,NA(),GETPIVOTDATA("ITL",'ITL-PIVOT'!$A$3,"KV%",$A13,"Experiment",H$5,"date",H$6)) -> #N/A | I13: =IF(GETPIVOTDATA("ITL",'ITL-PIVOT'!$A$3,"KV%",$A13,"Experiment",I$5,"date",I$6)=0,NA(),GETPIVOTDATA("ITL",'ITL-PIVOT'!$A$3,"KV%",$A13,"Experiment",I$5,"date",I$6)) -> #N/A | ... M13: =IF(GETPIVOTDATA("ITL",'ITL-PIVOT'!$A$3,"KV%",$A13,"Experiment",M$5,"date",M$6)=0,NA(),GETPIVOTDATA("ITL",'ITL-PIVOT'!$A$3,"KV%",$A13,"Experiment",M$5,"date",M$6)) -> #N/A
A14: =IF('ITL-PIVOT'!A12=0,NA(),'ITL-PIVOT'!A12) -> 0.027674918 | B14: =IF(GETPIVOTDATA("ITL",'ITL-PIVOT'!$A$3,"KV%",$A14,"Experiment",B$5,"date",B$6)=0,NA(),GETPIVOTDATA("ITL",'ITL-PIVOT'!$A$3,"KV%",$A14,"Experiment",B$5,"date",B$6)) -> #N/A | C14: =IF(GETPIVOTDATA("ITL",'ITL-PIVOT'!$A$3,"KV%",$A14,"Experiment",C$5,"date",C$6)=0,NA(),GETPIVOTDATA("ITL",'ITL-PIVOT'!$A$3,"KV%",$A14,"Experiment",C$5,"date",C$6)) -> #N/A | D14: =IF(GETPIVOTDATA("ITL",'ITL-PIVOT'!$A$3,"KV%",$A14,"Experiment",D$5,"date",D$6)=0,NA(),GETPIVOTDATA("ITL",'ITL-PIVOT'!$A$3,"KV%",$A14,"Experiment",D$5,"date",D$6)) -> #N/A | E14: =IF(GETPIVOTDATA("ITL",'ITL-PIVOT'!$A$3,"KV%",$A14,"Experiment",E$5,"date",E$6)=0,NA(),GETPIVOTDATA("ITL",'ITL-PIVOT'!$A$3,"KV%",$A14,"Experiment",E$5,"date",E$6)) -> #N/A | F14: =IF(GETPIVOTDATA("ITL",'ITL-PIVOT'!$A$3,"KV%",$A14,"Experiment",F$5,"date",F$6)=0,NA(),GETPIVOTDATA("ITL",'ITL-PIVOT'!$A$3,"KV%",$A14,"Experiment",F$5,"date",F$6)) -> 0.0096372251 | G14: =IF(GETPIVOTDATA("ITL",'ITL-PIVOT'!$A$3,"KV%",$A14,"Experiment",G$5,"date",G$6)=0,NA(),GETPIVOTDATA("ITL",'ITL-PIVOT'!$A$3,"KV%",$A14,"Experiment",G$5,"date",G$6)) -> #N/A | H14: =IF(GETPIVOTDATA("ITL",'ITL-PIVOT'!$A$3,"KV%",$A14,"Experiment",H$5,"date",H$6)=0,NA(),GETPIVOTDATA("ITL",'ITL-PIVOT'!$A$3,"KV%",$A14,"Experiment",H$5,"date",H$6)) -> #N/A | I14: =IF(GETPIVOTDATA("ITL",'ITL-PIVOT'!$A$3,"KV%",$A14,"Experiment",I$5,"date",I$6)=0,NA(),GETPIVOTDATA("ITL",'ITL-PIVOT'!$A$3,"KV%",$A14,"Experiment",I$5,"date",I$6)) -> #N/A | ... M14: =IF(GETPIVOTDATA("ITL",'ITL-PIVOT'!$A$3,"KV%",$A14,"Experiment",M$5,"date",M$6)=0,NA(),GETPIVOTDATA("ITL",'ITL-PIVOT'!$A$3,"KV%",$A14,"Experiment",M$5,"date",M$6)) -> #N/A
A15: =IF('ITL-PIVOT'!A13=0,NA(),'ITL-PIVOT'!A13) -> 0.031234376 | B15: =IF(GETPIVOTDATA("ITL",'ITL-PIVOT'!$A$3,"KV%",$A15,"Experiment",B$5,"date",B$6)=0,NA(),GETPIVOTDATA("ITL",'ITL-PIVOT'!$A$3,"KV%",$A15,"Experiment",B$5,"date",B$6)) -> #N/A | C15: =IF(GETPIVOTDATA("ITL",'ITL-PIVOT'!$A$3,"KV%",$A15,"Experiment",C$5,"date",C$6)=0,NA(),GETPIVOTDATA("ITL",'ITL-PIVOT'!$A$3,"KV%",$A15,"Experiment",C$5,"date",C$6)) -> #N/A | D15: =IF(GETPIVOTDATA("ITL",'ITL-PIVOT'!$A$3,"KV%",$A15,"Experiment",D$5,"date",D$6)=0,NA(),GETPIVOTDATA("ITL",'ITL-PIVOT'!$A$3,"KV%",$A15,"Experiment",D$5,"date",D$6)) -> #N/A | E15: =IF(GETPIVOTDATA("ITL",'ITL-PIVOT'!$A$3,"KV%",$A15,"Experiment",E$5,"date",E$6)=0,NA(),GETPIVOTDATA("ITL",'ITL-PIVOT'!$A$3,"KV%",$A15,"Experiment",E$5,"date",E$6)) -> 0.0096815497 | F15: =IF(GETPIVOTDATA("ITL",'ITL-PIVOT'!$A$3,"KV%",$A15,"Experiment",F$5,"date",F$6)=0,NA(),GETPIVOTDATA("ITL",'ITL-PIVOT'!$A$3,"KV%",$A15,"Experiment",F$5,"date",F$6)) -> #N/A | G15: =IF(GETPIVOTDATA("ITL",'ITL-PIVOT'!$A$3,"KV%",$A15,"Experiment",G$5,"date",G$6)=0,NA(),GETPIVOTDATA("ITL",'ITL-PIVOT'!$A$3,"KV%",$A15,"Experiment",G$5,"date",G$6)) -> #N/A | H15: =IF(GETPIVOTDATA("ITL",'ITL-PIVOT'!$A$3,"KV%",$A15,"Experiment",H$5,"date",H$6)=0,NA(),GETPIVOTDATA("ITL",'ITL-PIVOT'!$A$3,"KV%",$A15,"Experiment",H$5,"date",H$6)) -> #N/A | I15: =IF(GETPIVOTDATA("ITL",'ITL-PIVOT'!$A$3,"KV%",$A15,"Experiment",I$5,"date",I$6)=0,NA(),GETPIVOTDATA("ITL",'ITL-PIVOT'!$A$3,"KV%",$A15,"Experiment",I$5,"date",I$6)) -> #N/A | ... M15: =IF(GETPIVOTDATA("ITL",'ITL-PIVOT'!$A$3,"KV%",$A15,"Experiment",M$5,"date",M$6)=0,NA(),GETPIVOTDATA("ITL",'ITL-PIVOT'!$A$3,"KV%",$A15,"Experiment",M$5,"date",M$6)) -> #N/A
A16: =IF('ITL-PIVOT'!A14=0,NA(),'ITL-PIVOT'!A14) -> 0.035640373 | B16: =IF(GETPIVOTDATA("ITL",'ITL-PIVOT'!$A$3,"KV%",$A16,"Experiment",B$5,"date",B$6)=0,NA(),GETPIVOTDATA("ITL",'ITL-PIVOT'!$A$3,"KV%",$A16,"Experiment",B$5,"date",B$6)) -> #N/A | C16: =IF(GETPIVOTDATA("ITL",'ITL-PIVOT'!$A$3,"KV%",$A16,"Experiment",C$5,"date",C$6)=0,NA(),GETPIVOTDATA("ITL",'ITL-PIVOT'!$A$3,"KV%",$A16,"Experiment",C$5,"date",C$6)) -> 0.0080706953 | D16: =IF(GETPIVOTDATA("ITL",'ITL-PIVOT'!$A$3,"KV%",$A16,"Experiment",D$5,"date",D$6)=0,NA(),GETPIVOTDATA("ITL",'ITL-PIVOT'!$A$3,"KV%",$A16,"Experiment",D$5,"date",D$6)) -> #N/A | E16: =IF(GETPIVOTDATA("ITL",'ITL-PIVOT'!$A$3,"KV%",$A16,"Experiment",E$5,"date",E$6)=0,NA(),GETPIVOTDATA("ITL",'ITL-PIVOT'!$A$3,"KV%",$A16,"Experiment",E$5,"date",E$6)) -> #N/A | F16: =IF(GETPIVOTDATA("ITL",'ITL-PIVOT'!$A$3,"KV%",$A16,"Experiment",F$5,"date",F$6)=0,NA(),GETPIVOTDATA("ITL",'ITL-PIVOT'!$A$3,"KV%",$A16,"Experiment",F$5,"date",F$6)) -> #N/A | G16: =IF(GETPIVOTDATA("ITL",'ITL-PIVOT'!$A$3,"KV%",$A16,"Experiment",G$5,"date",G$6)=0,NA(),GETPIVOTDATA("ITL",'ITL-PIVOT'!$A$3,"KV%",$A16,"Experiment",G$5,"date",G$6)) -> #N/A | H16: =IF(GETPIVOTDATA("ITL",'ITL-PIVOT'!$A$3,"KV%",$A16,"Experiment",H$5,"date",H$6)=0,NA(),GETPIVOTDATA("ITL",'ITL-PIVOT'!$A$3,"KV%",$A16,"Experiment",H$5,"date",H$6)) -> #N/A | I16: =IF(GETPIVOTDATA("ITL",'ITL-PIVOT'!$A$3,"KV%",$A16,"Experiment",I$5,"date",I$6)=0,NA(),GETPIVOTDATA("ITL",'ITL-PIVOT'!$A$3,"KV%",$A16,"Experiment",I$5,"date",I$6)) -> #N/A | ... M16: =IF(GETPIVOTDATA("ITL",'ITL-PIVOT'!$A$3,"KV%",$A16,"Experiment",M$5,"date",M$6)=0,NA(),GETPIVOTDATA("ITL",'ITL-PIVOT'!$A$3,"KV%",$A16,"Experiment",M$5,"date",M$6)) -> #N/A
A17: =IF('ITL-PIVOT'!A15=0,NA(),'ITL-PIVOT'!A15) -> 0.036869666 | B17: =IF(GETPIVOTDATA("ITL",'ITL-PIVOT'!$A$3,"KV%",$A17,"Experiment",B$5,"date",B$6)=0,NA(),GETPIVOTDATA("ITL",'ITL-PIVOT'!$A$3,"KV%",$A17,"Experiment",B$5,"date",B$6)) -> 0.0081016796 | C17: =IF(GETPIVOTDATA("ITL",'ITL-PIVOT'!$A$3,"KV%",$A17,"Experiment",C$5,"date",C$6)=0,NA(),GETPIVOTDATA("ITL",'ITL-PIVOT'!$A$3,"KV%",$A17,"Experiment",C$5,"date",C$6)) -> #N/A | D17: =IF(GETPIVOTDATA("ITL",'ITL-PIVOT'!$A$3,"KV%",$A17,"Experiment",D$5,"date",D$6)=0,NA(),GETPIVOTDATA("ITL",'ITL-PIVOT'!$A$3,"KV%",$A17,"Experiment",D$5,"date",D$6)) -> #N/A | E17: =IF(GETPIVOTDATA("ITL",'ITL-PIVOT'!$A$3,"KV%",$A17,"Experiment",E$5,"date",E$6)=0,NA(),GETPIVOTDATA("ITL",'ITL-PIVOT'!$A$3,"KV%",$A17,"Experiment",E$5,"date",E$6)) -> #N/A | F17: =IF(GETPIVOTDATA("ITL",'ITL-PIVOT'!$A$3,"KV%",$A17,"Experiment",F$5,"date",F$6)=0,NA(),GETPIVOTDATA("ITL",'ITL-PIVOT'!$A$3,"KV%",$A17,"Experiment",F$5,"date",F$6)) -> #N/A | G17: =IF(GETPIVOTDATA("ITL",'ITL-PIVOT'!$A$3,"KV%",$A17,"Experiment",G$5,"date",G$6)=0,NA(),GETPIVOTDATA("ITL",'ITL-PIVOT'!$A$3,"KV%",$A17,"Experiment",G$5,"date",G$6)) -> #N/A | H17: =IF(GETPIVOTDATA("ITL",'ITL-PIVOT'!$A$3,"KV%",$A17,"Experiment",H$5,"date",H$6)=0,NA(),GETPIVOTDATA("ITL",'ITL-PIVOT'!$A$3,"KV%",$A17,"Experiment",H$5,"date",H$6)) -> #N/A | I17: =IF(GETPIVOTDATA("ITL",'ITL-PIVOT'!$A$3,"KV%",$A17,"Experiment",I$5,"date",I$6)=0,NA(),GETPIVOTDATA("ITL",'ITL-PIVOT'!$A$3,"KV%",$A17,"Experiment",I$5,"date",I$6)) -> #N/A | ... M17: =IF(GETPIVOTDATA("ITL",'ITL-PIVOT'!$A$3,"KV%",$A17,"Experiment",M$5,"date",M$6)=0,NA(),GETPIVOTDATA("ITL",'ITL-PIVOT'!$A$3,"KV%",$A17,"Experiment",M$5,"date",M$6)) -> #N/A
A18: =IF('ITL-PIVOT'!A16=0,NA(),'ITL-PIVOT'!A16) -> 0.039849347 | B18: =IF(GETPIVOTDATA("ITL",'ITL-PIVOT'!$A$3,"KV%",$A18,"Experiment",B$5,"date",B$6)=0,NA(),GETPIVOTDATA("ITL",'ITL-PIVOT'!$A$3,"KV%",$A18,"Experiment",B$5,"date",B$6)) -> #N/A | C18: =IF(GETPIVOTDATA("ITL",'ITL-PIVOT'!$A$3,"KV%",$A18,"Experiment",C$5,"date",C$6)=0,NA(),GETPIVOTDATA("ITL",'ITL-PIVOT'!$A$3,"KV%",$A18,"Experiment",C$5,"date",C$6)) -> 0.0082483981 | D18: =IF(GETPIVOTDATA("ITL",'ITL-PIVOT'!$A$3,"KV%",$A18,"Experiment",D$5,"date",D$6)=0,NA(),GETPIVOTDATA("ITL",'ITL-PIVOT'!$A$3,"KV%",$A18,"Experiment",D$5,"date",D$6)) -> #N/A | E18: =IF(GETPIVOTDATA("ITL",'ITL-PIVOT'!$A$3,"KV%",$A18,"Experiment",E$5,"date",E$6)=0,NA(),GETPIVOTDATA("ITL",'ITL-PIVOT'!$A$3,"KV%",$A18,"Experiment",E$5,"date",E$6)) -> #N/A | F18: =IF(GETPIVOTDATA("ITL",'ITL-PIVOT'!$A$3,"KV%",$A18,"Experiment",F$5,"date",F$6)=0,NA(),GETPIVOTDATA("ITL",'ITL-PIVOT'!$A$3,"KV%",$A18,"Experiment",F$5,"date",F$6)) -> #N/A | G18: =IF(GETPIVOTDATA("ITL",'ITL-PIVOT'!$A$3,"KV%",$A18,"Experiment",G$5,"date",G$6)=0,NA(),GETPIVOTDATA("ITL",'ITL-PIVOT'!$A$3,"KV%",$A18,"Experiment",G$5,"date",G$6)) -> #N/A | H18: =IF(GETPIVOTDATA("ITL",'ITL-PIVOT'!$A$3,"KV%",$A18,"Experiment",H$5,"date",H$6)=0,NA(),GETPIVOTDATA("ITL",'ITL-PIVOT'!$A$3,"KV%",$A18,"Experiment",H$5,"date",H$6)) -> #N/A | I18: =IF(GETPIVOTDATA("ITL",'ITL-PIVOT'!$A$3,"KV%",$A18,"Experiment",I$5,"date",I$6)=0,NA(),GETPIVOTDATA("ITL",'ITL-PIVOT'!$A$3,"KV%",$A18,"Experiment",I$5,"date",I$6)) -> #N/A | ... M18: =IF(GETPIVOTDATA("ITL",'ITL-PIVOT'!$A$3,"KV%",$A18,"Experiment",M$5,"date",M$6)=0,NA(),GETPIVOTDATA("ITL",'ITL-PIVOT'!$A$3,"KV%",$A18,"Experiment",M$5,"date",M$6)) -> #N/A
A19: =IF('ITL-PIVOT'!A17=0,NA(),'ITL-PIVOT'!A17) -> 0.041308812 | B19: =IF(GETPIVOTDATA("ITL",'ITL-PIVOT'!$A$3,"KV%",$A19,"Experiment",B$5,"date",B$6)=0,NA(),GETPIVOTDATA("ITL",'ITL-PIVOT'!$A$3,"KV%",$A19,"Experiment",B$5,"date",B$6)) -> #N/A | C19: =IF(GETPIVOTDATA("ITL",'ITL-PIVOT'!$A$3,"KV%",$A19,"Experiment",C$5,"date",C$6)=0,NA(),GETPIVOTDATA("ITL",'ITL-PIVOT'!$A$3,"KV%",$A19,"Experiment",C$5,"date",C$6)) -> #N/A | D19: =IF(GETPIVOTDATA("ITL",'ITL-PIVOT'!$A$3,"KV%",$A19,"Experiment",D$5,"date",D$6)=0,NA(),GETPIVOTDATA("ITL",'ITL-PIVOT'!$A$3,"KV%",$A19,"Experiment",D$5,"date",D$6)) -> 0.0090757149 | E19: =IF(GETPIVOTDATA("ITL",'ITL-PIVOT'!$A$3,"KV%",$A19,"Experiment",E$5,"date",E$6)=0,NA(),GETPIVOTDATA("ITL",'ITL-PIVOT'!$A$3,"KV%",$A19,"Experiment",E$5,"date",E$6)) -> #N/A | F19: =IF(GETPIVOTDATA("ITL",'ITL-PIVOT'!$A$3,"KV%",$A19,"Experiment",F$5,"date",F$6)=0,NA(),GETPIVOTDATA("ITL",'ITL-PIVOT'!$A$3,"KV%",$A19,"Experiment",F$5,"date",F$6)) -> #N/A | G19: =IF(GETPIVOTDATA("ITL",'ITL-PIVOT'!$A$3,"KV%",$A19,"Experiment",G$5,"date",G$6)=0,NA(),GETPIVOTDATA("ITL",'ITL-PIVOT'!$A$3,"KV%",$A19,"Experiment",G$5,"date",G$6)) -> #N/A | H19: =IF(GETPIVOTDATA("ITL",'ITL-PIVOT'!$A$3,"KV%",$A19,"Experiment",H$5,"date",H$6)=0,NA(),GETPIVOTDATA("ITL",'ITL-PIVOT'!$A$3,"KV%",$A19,"Experiment",H$5,"date",H$6)) -> #N/A | I19: =IF(GETPIVOTDATA("ITL",'ITL-PIVOT'!$A$3,"KV%",$A19,"Experiment",I$5,"date",I$6)=0,NA(),GETPIVOTDATA("ITL",'ITL-PIVOT'!$A$3,"KV%",$A19,"Experiment",I$5,"date",I$6)) -> #N/A | ... M19: =IF(GETPIVOTDATA("ITL",'ITL-PIVOT'!$A$3,"KV%",$A19,"Experiment",M$5,"date",M$6)=0,NA(),GETPIVOTDATA("ITL",'ITL-PIVOT'!$A$3,"KV%",$A19,"Experiment",M$5,"date",M$6)) -> #N/A
... A222: =IF('ITL-PIVOT'!A220=0,NA(),'ITL-PIVOT'!A220) -> 0.90925288 | B222: =IF(GETPIVOTDATA("ITL",'ITL-PIVOT'!$A$3,"KV%",$A222,"Experiment",B$5,"date",B$6)=0,NA(),GETPIVOTDATA("ITL",'ITL-PIVOT'!$A$3,"KV%",$A222,"Experiment",B$5,"date",B$6)) -> #N/A | C222: =IF(GETPIVOTDATA("ITL",'ITL-PIVOT'!$A$3,"KV%",$A222,"Experiment",C$5,"date",C$6)=0,NA(),GETPIVOTDATA("ITL",'ITL-PIVOT'!$A$3,"KV%",$A222,"Experiment",C$5,"date",C$6)) -> 0.054345286 | D222: =IF(GETPIVOTDATA("ITL",'ITL-PIVOT'!$A$3,"KV%",$A222,"Experiment",D$5,"date",D$6)=0,NA(),GETPIVOTDATA("ITL",'ITL-PIVOT'!$A$3,"KV%",$A222,"Experiment",D$5,"date",D$6)) -> #N/A | E222: =IF(GETPIVOTDATA("ITL",'ITL-PIVOT'!$A$3,"KV%",$A222,"Experiment",E$5,"date",E$6)=0,NA(),GETPIVOTDATA("ITL",'ITL-PIVOT'!$A$3,"KV%",$A222,"Experiment",E$5,"date",E$6)) -> #N/A | F222: =IF(GETPIVOTDATA("ITL",'ITL-PIVOT'!$A$3,"KV%",$A222,"Experiment",F$5,"date",F$6)=0,NA(),GETPIVOTDATA("ITL",'ITL-PIVOT'!$A$3,"KV%",$A222,"Experiment",F$5,"date",F$6)) -> #N/A | G222: =IF(GETPIVOTDATA("ITL",'ITL-PIVOT'!$A$3,"KV%",$A222,"Experiment",G$5,"date",G$6)=0,NA(),GETPIVOTDATA("ITL",'ITL-PIVOT'!$A$3,"KV%",$A222,"Experiment",G$5,"date",G$6)) -> #N/A | H222: =IF(GETPIVOTDATA("ITL",'ITL-PIVOT'!$A$3,"KV%",$A222,"Experiment",H$5,"date",H$6)=0,NA(),GETPIVOTDATA("ITL",'ITL-PIVOT'!$A$3,"KV%",$A222,"Experiment",H$5,"date",H$6)) -> #N/A | I222: =IF(GETPIVOTDATA("ITL",'ITL-PIVOT'!$A$3,"KV%",$A222,"Experiment",I$5,"date",I$6)=0,NA(),GETPIVOTDATA("ITL",'ITL-PIVOT'!$A$3,"KV%",$A222,"Experiment",I$5,"date",I$6)) -> #N/A | ... M222: =IF(GETPIVOTDATA("ITL",'ITL-PIVOT'!$A$3,"KV%",$A222,"Experiment",M$5,"date",M$6)=0,NA(),GETPIVOTDATA("ITL",'ITL-PIVOT'!$A$3,"KV%",$A222,"Experiment",M$5,"date",M$6)) -> #N/A

Sheet data
S1: Maximal KV cache Load | V1: Average Out-Token Load | AA1: Est Max Tok | AC1: Est Max Tok | AJ1: No queue | BB1: Max N Threshold
D2: =AVERAGE(INDIRECT("Table1[["&D$5&"]]")) -> 0.40966159 | H2: =AVERAGE(INDIRECT("Table1[["&H$5&"]]")) -> 2.1156208 | I2: =AVERAGE(INDIRECT("Table1[["&I$5&"]]")) -> 0.37342867 | J2: =AVERAGE(INDIRECT("Table1[["&J$5&"]]")) -> 2.7171722 | K2: =AVERAGE(INDIRECT("Table1[["&K$5&"]]")) -> 5.7061617 | L2: =AVERAGE(INDIRECT("Table1[["&L$5&"]]")) -> 6.2199588 | M2: =AVERAGE(INDIRECT("Table1[["&M$5&"]]")) -> 0.029235323 | N2: =AVERAGE(INDIRECT("Table1[["&N$5&"]]")) -> 13.596276 | O2: =AVERAGE(INDIRECT("Table1[["&O$5&"]]")) -> 18604.567 | ... R2: =AVERAGE(INDIRECT("Table1[["&R$5&"]]")) -> 42.862791 | S2: 0.8 | V2: 0.5 | Y2: =MAX(Table1[Ratio]) -> 60 | AA2: =AVERAGE(Table1[MaxTok(N)]) -> 481946.05 | AC2: =AVERAGE(Table1[MaxTok(Run)]) -> 387912.26 | AE2: =AVERAGE(Table1[MaxTok(MaxRun)]) -> 387879.62 | AI2: =AVERAGE(Table1[GPSestErr]) -> 0.87289793 | AO2: =([@[KV%]]*[@[MaxTok(Run)]]/([@RPS]*[@[tok/req]])-[@Prefill])/[@[Out-Tok]] | BB2: 0.75 | BP2: 1000 | BQ2: 0.005 | BR2: 0.1 | BS2: 0.01 | BT2: 1 | BU2: 5 | BV2: 1000
A3: =COUNTA(INDIRECT("Table1[["&A$5&"]]")) -> 215 | B3: =COUNTA(INDIRECT("Table1[["&B$5&"]]")) -> 215 | C3: =COUNTA(INDIRECT("Table1[["&C$5&"]]")) -> 215 | D3: =COUNTA(INDIRECT("Table1[["&D$5&"]]")) -> 215 | E3: =COUNTA(INDIRECT("Table1[["&E$5&"]]")) -> 215 | F3: =COUNTA(INDIRECT("Table1[["&F$5&"]]")) -> 215 | G3: =COUNTA(INDIRECT("Table1[["&G$5&"]]")) -> 69 | H3: =COUNTA(INDIRECT("Table1[["&H$5&"]]")) -> 215 | ... R3: =COUNTA(INDIRECT("Table1[["&R$5&"]]")) -> 215 | AA3: =_xlfn.STDEV.S(Table1[MaxTok(N)]) -> 101714.2 | AC3: =_xlfn.STDEV.S(Table1[MaxTok(Run)]) -> 1495.9741 | AE3: =_xlfn.STDEV.S(Table1[MaxTok(MaxRun)]) -> 2978.5083 | AI3: =_xlfn.STDEV.S(Table1[GPSestErr]) -> 0.13935029 | BP3: [@[tok/req]] | BQ3: [@ITL] | BR3: [@Kvcache] | BS3: [@Kvcache] | BT3: [@Run] | BU3: [@Ratio] | BV3: [@[In-Tok]]
A4: Requests | U4: Demand | Z4: Estimated Token Load | AF4: Current Supply | BP4: Buckets | CQ4: 0.5 | CR4: 388142 | CS4: 387973 | CT4: 311323 | CU4: 388142 | CV4: 0.8
A5: In-Tok | B5: Out-Tok | C5: RPS | D5: KV% | E5: Experiment | F5: date | G5: PHR | H5: TTFT | I5: Prefill | J5: L_TTFT | K5: L_P95_TTFT | L5: L_P98_TTFT | M5: ITL | N5: E2E | O5: PPS | P5: GPS | Q5: Run | R5: MaxRun | S5: Kvcache | T5: MaxKvcache | U5: tok/sec | V5: tok/req | W5: In/sec | X5: Out/sec | Y5: Ratio | Z5: tok(N) | AA5: MaxTok(N) | AB5: tok(Run) | AC5: MaxTok(Run) | AD5: tok(MaxRun) | AE5: MaxTok(MaxRun) | AF5: Nprefill | AG5: Ndecode | AH5: N | AI5: GPSestErr | AJ5: estTTFT | AK5: TTFT% | AL5: estPrefill | AM5: Prefill% | AN5: Prefill/TTFT | AO5: estITL | AP5: estITL% | AQ5: estDecode | AR5: param | AS5: E2E-sat | AT5: estE2E | AU5: E2E% | AV5: estRPS | AW5: RPS(IL) | AX5: RPS(IL)% | AY5: RPS(OL) | AZ5: RPS(OL)% | BA5: N-max | BB5: N% | BC5: RPS success | BD5: est-In-Tok3 | BE5: err%-In-Tok3 | BF5: est-Out-Tok3 | BG5: err%-Out-Tok3 | BH5: est-Tok/Req3 | BI5: err%-Tok/Req3 | BJ5: est-N-max3 | BK5: err%-N-max3 | BL5: est-Tok/Req | BM5: err%-Tok/Req | BN5: est-N-max2 | BO5: est-N-max | BP5: B-tok/req | BQ5: B-ITL | BR5: B-Kvcache | BS5: B2-Kvcache | BT5: B-Run | BU5: B-Ratio | BV5: B-In-Tok | BW5: Column28 | BX5: Column29 | BY5: Column30 | BZ5: Column31 | CA5: Demand-T | CB5: Supply | CC5: Mrate | CD5: OTS | CE5: OTS-D | CF5: S/D | CH5: e2e sat | CI5: GPS*ITL | CJ5: PPS*PREFILL/IL | CK5: N2 | CL5: PPS/IL | CM5: GPS/OL | CN5: RUN/E2E | CO5: N/E2E | CP5: 2 | CQ5: Tokens load | CR5: C(R) | CS5: C(MaxR) | CT5: C(N) | CU5: N(maxT) | CV5: N%2 | CW5: Column1 | CX5: Column2 | CY5: relative cache
A6: 1000 | B6: 300 | C6: 2 | D6: =Table1[[#This Row],[Kvcache]] -> 0.010150558 | E6: 1-15K,300 | F6: 46092 | H6: 0.037026038 | I6: 0.032088905 | J6: 0.59547005 | K6: 0.7305009 | L6: 0.9761506 | M6: 0.0065961989 | N6: 2.0093214 | O6: 2261.5283 | P6: 633.58861 | Q6: 3.4068627 | R6: 8 | S6: 0.010150558 | T6: 0.024075511 | U6: =(Table1[[#This Row],[In-Tok]]+Table1[[#This Row],[Out-Tok]])*Table1[[#This Row],[RPS]] -> 2600 | V6: =Table1[[#This Row],[In-Tok]]+AvgOutLoad*Table1[[#This Row],[Out-Tok]] -> 1150 | W6: =Table1[[#This Row],[In-Tok]]*Table1[[#This Row],[RPS]] -> 2000 | X6: =Table1[[#This Row],[Out-Tok]]*Table1[[#This Row],[RPS]] -> 600 | Y6: =Table1[[#This Row],[In-Tok]]/Table1[[#This Row],[Out-Tok]] -> 3.3333333 | Z6: =Table1[[#This Row],[In-Tok]]*Table1[[#This Row],[N]]+AvgOutLoad*Table1[[#This Row],[Out-Tok]]*Table1[[#This Row],[Ndecode]] -> 4878.7379 | AA6: =Table1[[#This Row],[tok(N)]]/Table1[[#This Row],[Kvcache]] -> 480637.43 | AB6: =Table1[[#This Row],[tok/req]]*Table1[[#This Row],[Run]] -> 3917.8922 | AC6: =Table1[[#This Row],[tok(Run)]]/Table1[[#This Row],[Kvcache]] -> 385978.03 | AD6: =Table1[[#This Row],[tok/req]]*Table1[[#This Row],[MaxRun]] -> 9200 | AE6: =Table1[[#This Row],[tok(MaxRun)]]/Table1[[#This Row],[MaxKvcache]] -> 382131.04 | AF6: =Table1[[#This Row],[PPS]]*Table1[[#This Row],[Prefill]]/Table1[[#This Row],[In-Tok]] -> 0.072569968 | AG6: =Table1[[#This Row],[GPS]]*Table1[[#This Row],[ITL]] -> 4.1792765 | AH6: =Table1[[#This Row],[Nprefill]]+Table1[[#This Row],[Ndecode]] -> 4.2518464 | AI6: =Table1[[#This Row],[Run]]/Table1[[#This Row],[ITL]]/Table1[[#This Row],[GPS]] -> 0.81518004 | AJ6: =Table1[[#This Row],[Prefill]]+Table1[[#This Row],[ITL]] -> 0.038685104 | AK6: =Table1[[#This Row],[TTFT]]/Table1[[#This Row],[estTTFT]] -> 0.95711358 | AL6: =Table1[[#This Row],[In-Tok]]*Table1[[#This Row],[RPS]]/Table1[[#This Row],[PPS]] -> 0.8843577 | AM6: =Table1[[#This Row],[Prefill]]/Table1[[#This Row],[estPrefill]] -> 0.036284984 | AN6: =Table1[[#This Row],[Prefill]]/Table1[[#This Row],[TTFT]] -> 0.86665781 | AO6: =Table1[[#This Row],[Run]]/(Table1[[#This Row],[Out-Tok]]*Table1[[#This Row],[RPS]]) -> 0.0056781046 | AP6: =Table1[[#This Row],[ITL]]/Table1[[#This Row],[estITL]] -> 1.1616903 | AQ6: =Table1[[#This Row],[E2E]]-Table1[[#This Row],[TTFT]]+Table1[[#This Row],[ITL]] -> 1.9788915 | AR6: =Table1[[#This Row],[estDecode]]/Table1[[#This Row],[Run]] -> 0.5808545 | AS6: =Table1[[#This Row],[Prefill]]+Table1[[#This Row],[Out-Tok]]*Table1[[#This Row],[ITL]] -> 2.0109486 | AT6: =Table1[[#This Row],[estPrefill]]+Table1[[#This Row],[Out-Tok]]*Table1[[#This Row],[ITL]] -> 2.8632174 | AU6: =Table1[[#This Row],[E2E]]/Table1[[#This Row],[estE2E]] -> 0.70177047 | AV6: =Table1[[#This Row],[N]]/Table1[[#This Row],[estE2E]] -> 1.4849891 | AW6: =Table1[[#This Row],[PPS]]/Table1[[#This Row],[In-Tok]] -> 2.2615283 | AX6: =Table1[[#This Row],[RPS]]/Table1[[#This Row],[RPS(IL)]] -> 0.8843577 | AY6: =Table1[[#This Row],[GPS]]/Table1[[#This Row],[Out-Tok]] -> 2.111962 | AZ6: =Table1[[#This Row],[RPS]]/Table1[[#This Row],[RPS(OL)]] -> 0.94698672 | BA6: =MaxTok/Table1[[#This Row],[tok/req]] -> 337.31501 | BB6: =Table1[[#This Row],[N]]/Table1[[#This Row],[N-max]] -> 0.012604973 | BC6: =Table1[[#This Row],[RPS]] -> 2 | BD6: =Table1[[#This Row],[PPS]]/Table1[[#This Row],[RPS success]] -> 1130.7642 | BE6: =ABS(Table1[[#This Row],[est-In-Tok3]]-Table1[[#This Row],[In-Tok]])/Table1[[#This Row],[In-Tok]] -> 0.13076417 | BF6: =Table1[[#This Row],[GPS]]/Table1[[#This Row],[RPS success]] -> 316.79431 | BG6: =ABS(Table1[[#This Row],[est-Out-Tok3]]-Table1[[#This Row],[Out-Tok]])/Table1[[#This Row],[Out-Tok]] -> 0.055981019 | BH6: =Table1[[#This Row],[est-In-Tok3]]+AvgOutLoad*Table1[[#This Row],[est-Out-Tok3]] -> 1289.1613 | BI6: =ABS(Table1[[#This Row],[est-Tok/Req3]]-Table1[[#This Row],[tok/req]])/Table1[[#This Row],[tok/req]] -> 0.12100984 | BJ6: =MaxTok/Table1[[#This Row],[est-Tok/Req3]] -> 300.90281 | BK6: =ABS(Table1[[#This Row],[est-N-max3]]-Table1[[#This Row],[N-max]])/Table1[[#This Row],[N-max]] -> 0.10794717 | BL6: =MaxTok*Table1[[#This Row],[Kvcache]]/Table1[[#This Row],[Run]] -> 1155.7629 | BM6: =ABS(Table1[[#This Row],[est-Tok/Req]]-Table1[[#This Row],[tok/req]])/Table1[[#This Row],[tok/req]] -> 0.0050112575 | BN6: =MaxTok/Table1[[#This Row],[est-Tok/Req]] -> 335.63307 | BO6: =Table1[[#This Row],[Run]]/Table1[[#This Row],[Kvcache]] -> 335.63307 | BP6: {=_xlfn.CEILING.MATH(INDIRECT("Table1"&BP$3)/BP$2)*BP$2} -> 2000 | BQ6: {=_xlfn.CEILING.MATH(INDIRECT("Table1"&BQ$3)/BQ$2)*BQ$2} -> 0.01 | BR6: {=_xlfn.CEILING.MATH(INDIRECT("Table1"&BR$3)/BR$2)*BR$2} -> 0.1 | BS6: {=_xlfn.CEILING.MATH(INDIRECT("Table1"&BS$3)/BS$2)*BS$2} -> 0.02 | BT6: {=_xlfn.CEILING.MATH(INDIRECT("Table1"&BT$3)/BT$2)*BT$2} -> 4 | BU6: {=_xlfn.CEILING.MATH(INDIRECT("Table1"&BU$3)/BU$2)*BU$2} -> 5 | BV6: {=_xlfn.CEILING.MATH(INDIRECT("Table1"&BV$3)/BV$2)*BV$2} -> 1000 | BY6: 0.024075511 | CA6: =(Table1[[#This Row],[In-Tok]]+Table1[[#This Row],[Out-Tok]])*Table1[[#This Row],[RPS]] -> 2600 | CB6: =R6*(A6+B6/2)/T6 -> 382131.04 | CC6: =Table1[[#This Row],[Supply]]/(Table1[[#This Row],[Prefill]]+Table1[[#This Row],[Out-Tok]]*Table1[[#This Row],[ITL]]) -> 190025.27 | CD6: =Table1[[#This Row],[MaxRun]]/Table1[[#This Row],[ITL]] -> 1212.8197 | CE6: =Table1[[#This Row],[Out-Tok]]*Table1[[#This Row],[RPS]] -> 600 | CF6: =Table1[[#This Row],[Supply]]/Table1[[#This Row],[Demand-T]] -> 146.97348 | CH6: =Table1[[#This Row],[Prefill]]+Table1[[#This Row],[Out-Tok]]*Table1[[#This Row],[ITL]] -> 2.0109486 | CI6: =Table1[[#This Row],[GPS]]*Table1[[#This Row],[ITL]] -> 4.1792765 | CJ6: =Table1[[#This Row],[PPS]]*Table1[[#This Row],[Prefill]]/Table1[[#This Row],[In-Tok]] -> 0.072569968 | CK6: =CI6+CJ6 -> 4.2518464 | CL6: =Table1[[#This Row],[PPS]]/Table1[[#This Row],[In-Tok]] -> 2.2615283 | CM6: =Table1[[#This Row],[GPS]]/Table1[[#This Row],[Out-Tok]] -> 2.111962 | CN6: =Table1[[#This Row],[Run]]/Table1[[#This Row],[E2E]] -> 1.695529 | CO6: =Table1[[#This Row],[N2]]/Table1[[#This Row],[E2E]] -> 2.1160609 | CQ6: =Table1[[#This Row],[In-Tok]]+AvgOutLoad*Table1[[#This Row],[Out-Tok]] -> 1150 | CR6: =CD6*CQ6/CF6 -> 9489.7575 | CS6: =CE6*CQ6/CG6 -> #DIV/0! | CT6: =(CJ6*M6+CI6*CQ6)/CG6 -> #DIV/0! | CU6: =$CL$4/CQ6 -> 0 | CV6: =CK6/CU6 -> #DIV/0! | CW6: =Table1[[#This Row],[N(maxT)]]/Table1[[#This Row],[e2e sat]] -> 0 | CX6: =Table1[[#This Row],[RPS]]/CW6 -> #DIV/0! | CY6: =Table1[[#This Row],[Kvcache]]/$T$4 -> #DIV/0!
